<mujoco>
    <option timestep="0.0002" />
    <actuator>
       
        <motor joint="hinge_1" name="actuator_motor" gear="100"/>
        <motor joint="hinge_2" name="actuator2_motor2" gear="100"/>
        <motor joint="hinge_angle" name="actuator_angle" gear="100"/>
         <motor joint="hinge_3" name="actuator3_motor3" gear="100"/>
    </actuator>
    <asset>
        <material name="blue_" rgba="0 0 1 1" />
        <material name="green" rgba="0 1 0 1" />
        <material name="red__" rgba="1 0 0 1" />
        <material name="white" rgba="1 1 1 1" />
    </asset>
    <worldbody>
        <geom type="plane" size="10 10 0.1" pos="0 0 -5" rgba=".9 0 0 1" />
        <light diffuse=".5 .5 .5" pos="0 0 3" dir="0 0 -1" />
        <body name="link_0" pos="0 0 0">
            <joint name="hinge_3" pos="0.5 -1 0" axis="0 0 1" />
            <geom type="cylinder" size=".3 .5" pos="0.5 -1 0" euler="0 0 90" material="green" mass="0.1"/>
            <body name="link_1" pos="0 0 0">
                <joint name="hinge_angle" pos="0.5 0 0" axis="0 1 0" />
                <geom type="cylinder" size=".3 .5" pos="0.5 -0.1 0" euler="90 0 0" material="green" mass="0.1"/>
                <body name="link_2" pos="1 0 0" euler="0 0 0">
                    <joint name="hinge_1" pos="0 0 0" axis="1 0 0" />
                    <geom type="box" size=".1 .25 2" pos="0 1.75 0" euler="90 0 0" material="blue_" mass="0.3"/>
                    <geom type="box" size=".1 .25 2" pos="-1 1.75 0" euler="90 0 0" material="blue_" mass="0.3"/>
                    <body name="link_3" pos="-0.5 3.5 0" euler="0 0 0">
                        <joint name="hinge_2" pos="0 0 0" axis="1 0 0" />
                        <geom type="box" size=".2 .2 2" pos="0 0 2" euler="0 0 0" material="red__" mass="0.3"/>
                        <geom type="cylinder" size=".25 .5" pos="0 0 0" euler="0 90 0" material="red__" mass="0.1"/>
                        <geom type="sphere" size=".4" pos="0 0 4" euler="0 90 0" material="red__" mass="0.1"/>
                    </body>
                </body>
            </body>
        </body>
    </worldbody>

    <contact>
    </contact>
</mujoco>